[DEBUG] https://api.github.com:443 "GET /repos/tensorflow/tensorflow/issues/comments/245992647/reactions HTTP/1.1" 200 None
[DEBUG] https://api.github.com:443 "GET /repos/tensorflow/tensorflow/issues/comments/247174513/reactions HTTP/1.1" 200 2
[DEBUG] https://api.github.com:443 "GET /repos/tensorflow/tensorflow/issues/comments/247331616/reactions HTTP/1.1" 200 2
[DEBUG] https://api.github.com:443 "GET /repos/tensorflow/tensorflow/issues/comments/248138158/reactions HTTP/1.1" 200 2
[DEBUG] https://api.github.com:443 "GET /repos/tensorflow/tensorflow/issues/comments/250077922/reactions HTTP/1.1" 200 2
[DEBUG] https://api.github.com:443 "GET /repos/tensorflow/tensorflow/issues/comments/250145975/reactions HTTP/1.1" 200 2
Traceback (most recent call last):
  File "C:\Users\svelderr\.pyenv\pyenv-win\versions\3.9.6\lib\site-packages\urllib3\connectionpool.py", line 787, in urlopen
    response = self._make_request(
  File "C:\Users\svelderr\.pyenv\pyenv-win\versions\3.9.6\lib\site-packages\urllib3\connectionpool.py", line 534, in _make_request
    response = conn.getresponse()
  File "C:\Users\svelderr\.pyenv\pyenv-win\versions\3.9.6\lib\site-packages\urllib3\connection.py", line 516, in getresponse
    httplib_response = super().getresponse()
  File "C:\Users\svelderr\.pyenv\pyenv-win\versions\3.9.6\lib\http\client.py", line 1349, in getresponse
    response.begin()
  File "C:\Users\svelderr\.pyenv\pyenv-win\versions\3.9.6\lib\http\client.py", line 316, in begin
    version, status, reason = self._read_status()
  File "C:\Users\svelderr\.pyenv\pyenv-win\versions\3.9.6\lib\http\client.py", line 285, in _read_status
    raise RemoteDisconnected("Remote end closed connection without"
http.client.RemoteDisconnected: Remote end closed connection without response

During handling of the above exception, another exception occurred:

Traceback (most recent call last):
  File "C:\Users\svelderr\.pyenv\pyenv-win\versions\3.9.6\lib\site-packages\requests\adapters.py", line 667, in send
    resp = conn.urlopen(
  File "C:\Users\svelderr\.pyenv\pyenv-win\versions\3.9.6\lib\site-packages\urllib3\connectionpool.py", line 841, in urlopen
    retries = retries.increment(
  File "C:\Users\svelderr\.pyenv\pyenv-win\versions\3.9.6\lib\site-packages\urllib3\util\retry.py", line 474, in increment
    raise reraise(type(error), error, _stacktrace)
  File "C:\Users\svelderr\.pyenv\pyenv-win\versions\3.9.6\lib\site-packages\urllib3\util\util.py", line 38, in reraise
    raise value.with_traceback(tb)
  File "C:\Users\svelderr\.pyenv\pyenv-win\versions\3.9.6\lib\site-packages\urllib3\connectionpool.py", line 787, in urlopen
    response = self._make_request(
  File "C:\Users\svelderr\.pyenv\pyenv-win\versions\3.9.6\lib\site-packages\urllib3\connectionpool.py", line 534, in _make_request
    response = conn.getresponse()
  File "C:\Users\svelderr\.pyenv\pyenv-win\versions\3.9.6\lib\site-packages\urllib3\connection.py", line 516, in getresponse
    httplib_response = super().getresponse()
  File "C:\Users\svelderr\.pyenv\pyenv-win\versions\3.9.6\lib\http\client.py", line 1349, in getresponse
    response.begin()
  File "C:\Users\svelderr\.pyenv\pyenv-win\versions\3.9.6\lib\http\client.py", line 316, in begin
    version, status, reason = self._read_status()
  File "C:\Users\svelderr\.pyenv\pyenv-win\versions\3.9.6\lib\http\client.py", line 285, in _read_status
    raise RemoteDisconnected("Remote end closed connection without"
urllib3.exceptions.ProtocolError: ('Connection aborted.', RemoteDisconnected('Remote end closed connection without response'))

During handling of the above exception, another exception occurred:

Traceback (most recent call last):
  File "C:\ni-open-source\KPIs\python\raw data capture\data mining\main.py", line 331, in <module>
    main()
  File "C:\ni-open-source\KPIs\python\raw data capture\data mining\main.py", line 309, in main
    fetch_comments_for_all_issues(
  File "C:\ni-open-source\KPIs\python\raw data capture\data mining\fetch_comments.py", line 42, in fetch_comments_for_all_issues
    list_issue_comments_single_thread(
  File "C:\ni-open-source\KPIs\python\raw data capture\data mining\fetch_comments.py", line 90, in list_issue_comments_single_thread
    fetch_comment_reactions_single_thread(
  File "C:\ni-open-source\KPIs\python\raw data capture\data mining\fetch_comments.py", line 132, in fetch_comment_reactions_single_thread
    (resp,success)=robust_get_page(session,url,params={},
  File "C:\ni-open-source\KPIs\python\raw data capture\data mining\fetch_comments.py", line 17, in robust_get_page
    resp=session.get(url, params=params)
  File "C:\Users\svelderr\.pyenv\pyenv-win\versions\3.9.6\lib\site-packages\requests\sessions.py", line 602, in get
    return self.request("GET", url, **kwargs)
  File "C:\Users\svelderr\.pyenv\pyenv-win\versions\3.9.6\lib\site-packages\requests\sessions.py", line 589, in request
    resp = self.send(prep, **send_kwargs)
  File "C:\Users\svelderr\.pyenv\pyenv-win\versions\3.9.6\lib\site-packages\requests\sessions.py", line 703, in send
    r = adapter.send(request, **kwargs)
  File "C:\Users\svelderr\.pyenv\pyenv-win\versions\3.9.6\lib\site-packages\requests\adapters.py", line 682, in send
    raise ConnectionError(err, request=request)
requests.exceptions.ConnectionError: ('Connection aborted.', RemoteDisconnected('Remote end closed connection without response'))

C:\ni-open-source\KPIs\python\raw data capture\data mining>
